---
created: 2023-11-03T22:29
updated: 2023-11-08T10:54
---
* [ ] 1.10 `错误处理`
    * [ ] 1.10.1 `错误处理，"try...catch"` (2023/10/19)[点击](https://zh.javascript.info/try-catch)
    * [ ] 1.10.2 `自定义 Error，扩展 Error` (2023/10/19)[点击](https://zh.javascript.info/custom-errors)
# 1.10.1 `错误处理，"try...catch"` (2023/10/19)[点击](https://zh.javascript.info/try-catch)
## [“try…catch” 语法](https://zh.javascript.info/try-catch#trycatch-yu-fa)
`try...catch` 结构由两部分组成：`try` 和 `catch`：
```js
try {
 // 代码...
} catch (err) {
 // 错误捕获
}
```
它按照以下步骤执行：

1. 首先，执行 `try {...}` 中的代码。
2. 如果这里没有错误，则忽略 `catch (err)`：执行到 `try` 的末尾并跳过 `catch` 继续执行。
3. 如果这里出现错误，则 `try` 执行停止，控制流转向 `catch (err)` 的开头。变量 `err`（我们可以使用任何名称）将包含一个 error 对象，该对象包含了所发生事件的详细信息。
4. 所以，`try {...}` 块内的 error 不会杀死脚本 —— 我们有机会在 `catch` 中处理它。
5. ![[Pasted image 20231026084218.png]]
6. `try...catch` 仅对运行时的 error 有效
7. ![[Pasted image 20231026084332.png]]
8. `try...catch` 同步执行
9. ![[Pasted image 20231026084452.png]]
## [Error 对象](https://zh.javascript.info/try-catch#error-dui-xiang)
发生错误时，JavaScript 会生成一个包含有关此 error 详细信息的对象。然后将该对象作为参数传递给 `catch`![[Pasted image 20231026084603.png]]
对于所有内建的 error，error 对象具有两个主要属性：
- **`name`：Error 名称。** 例如，对于一个未定义的变量，名称是 `"ReferenceError"`。
- **`message`：关于 error 的详细文字描述。**
- 还有其他非标准的属性在大多数环境中可用。其中被最广泛使用和支持的是：**`stack`：当前的调用栈**：用于调试目的的一个字符串，其中包含有关导致 error 的嵌套调用序列的信息。
- 例子：
- ![[Pasted image 20231026084906.png]]
## [可选的 “catch” 绑定](https://zh.javascript.info/try-catch#ke-xuan-de-catch-bang-ding)
![[Pasted image 20231026084953.png]]
## [使用 “try…catch”](https://zh.javascript.info/try-catch#shi-yong-trycatch)
![[Pasted image 20231026085145.png]]
在这儿，我们将 `catch` 块仅仅用于显示信息，但我们可以做更多的事：发送一个新的网络请求，向访问者建议一个替代方案，将有关错误的信息发送给记录日志的设备，……。所有这些都比代码“死掉”好得多。
## [抛出我们自定义的 error](https://zh.javascript.info/try-catch#pao-chu-wo-men-zi-ding-yi-de-error)
为了统一进行 error 处理，我们将使用 `throw` 操作符。
### [“throw” 操作符](https://zh.javascript.info/try-catch#throw-cao-zuo-fu)
![[Pasted image 20231026085318.png]]
技术上讲，我们可以将任何东西用作 error 对象。甚至可以是一个原始类型数据，例如数字或字符串，但最好使用对象，最好使用具有 `name` 和 `message` 属性的对象（某种程度上保持与内建 error 的兼容性）。

JavaScript 中有很多内建的标准 error 的构造器：`Error`，`SyntaxError`，`ReferenceError`，`TypeError` 等。我们也可以使用它们来创建 error 对象。
![[Pasted image 20231026085354.png]]
对于内建的 error（不是对于其他任何对象，仅仅是对于 error），`name` 属性刚好就是构造器的名字。`message` 则来自于参数（argument）。
![[Pasted image 20231026085436.png]]
![[Pasted image 20231026085505.png]]
![[Pasted image 20231026085555.png]]
在 `(*)` 标记的这一行，`throw` 操作符生成了包含着我们所给定的 `message` 的 `SyntaxError`，与 JavaScript 自己生成的方式相同。`try` 的执行立即停止，控制流转向 `catch` 块。

现在，`catch` 成为了所有 error 处理的唯一场所：对于 `JSON.parse` 和其他情况都适用。
## [再次抛出（Rethrowing）](https://zh.javascript.info/try-catch#zai-ci-pao-chu-rethrowing)
采用“重新抛出”技术。规则很简单：

**`catch` 应该只处理它知道的 error，并“抛出”所有其他 error。**

“再次抛出（rethrowing）”技术可以被更详细地解释为：

1. Catch 捕获所有 error。
2. 在 `catch (err) {...}` 块中，我们对 error 对象 `err` 进行分析。
3. 如果我们不知道如何处理它，那我们就 `throw err`。

- 通常，我们可以使用 `instanceof` 操作符判断错误类型
- 我们还可以从 `err.name` 属性中获取错误的类名。所有原生的错误都有这个属性。另一种方式是读取 `err.constructor.name`。
- ![[Pasted image 20231026090118.png]]
- 如果 `(*)` 标记的这行 `catch` 块中的 error 从 `try...catch` 中“掉了出来”，
- 那么它也可以被外部的 `try...catch` 结构（如果存在）捕获到，如果外部不存在这种结构，那么脚本就会被杀死。
- 所以，`catch` 块实际上只处理它知道该如何处理的 error，并“跳过”所有其他的 error。
- ![[Pasted image 20231026090348.png]]
- 上面这个例子中的 `readData` 只知道如何处理 `SyntaxError`，而外部的 `try...catch` 知道如何处理任意的 error。
## [try…catch…finally](https://zh.javascript.info/try-catch#trycatchfinally)
`try...catch` 结构可能还有一个代码子句（clause）：`finally`。

如果它存在，它在所有情况下都会被执行：

- `try` 之后，如果没有 error，
- `catch` 之后，如果有 error。
- ![[Pasted image 20231026090537.png]]
- ![[Pasted image 20231026090904.png]]
- ![[Pasted image 20231026090953.png]]
## [全局 catch](https://zh.javascript.info/try-catch#quan-ju-catch)
环境特定，这个部分的内容并不是 JavaScript 核心的一部分。
规范中没有相关内容，但是代码的执行环境一般会提供这种机制，因为它确实很有用。例如，Node.JS 有 [`process.on("uncaughtException")`](https://nodejs.org/api/process.html#process_event_uncaughtexception)。在浏览器中，我们可以将一个函数赋值给特殊的 [window.onerror](https://developer.mozilla.org/zh/docs/Web/API/GlobalEventHandlers/onerror) 属性，该函数将在发生未捕获的 error 时执行。
![[Pasted image 20231026091226.png]]
`message`

error 信息。

`url`

发生 error 的脚本的 URL。

`line`，`col`

发生 error 处的代码的行号和列号。

`error`

error 对象。

全局错误处理程序 `window.onerror` 的作用通常不是恢复脚本的执行 —— 如果发生编程错误，恢复脚本的执行几乎是不可能的，它的作用是将错误信息发送给开发者。

## [总结](https://zh.javascript.info/try-catch#zong-jie)

`try...catch` 结构允许我们处理执行过程中出现的 error。从字面上看，它允许“尝试”运行代码并“捕获”其中可能发生的 error。

![[Pasted image 20231026091404.png]]``

这儿可能会没有 `catch` 或者没有 `finally`，所以 `try...catch` 或 `try...finally` 都是可用的。

Error 对象包含下列属性：

- `message` _ 人类可读的 error 信息。
- `name` —— 具有 error 名称的字符串（Error 构造器的名称）。
- `stack`（没有标准，但得到了很好的支持）—— Error 发生时的调用栈。

如果我们不需要 error 对象，我们可以通过使用 `catch {` 而不是 `catch (err) {` 来省略它。

我们也可以使用 `throw` 操作符来生成自定义的 error。从技术上讲，`throw` 的参数可以是任何东西，但通常是继承自内建的 `Error` 类的 error 对象。下一章我们会详细介绍扩展 error。

再次抛出（rethrowing）是一种错误处理的重要模式：`catch` 块通常期望并知道如何处理特定的 error 类型，因此它应该再次抛出它不知道的 error。

即使我们没有 `try...catch`，大多数执行环境也允许我们设置“全局” error 处理程序来捕获“掉出（fall out）”的 error。在浏览器中，就是 `window.onerror`。
![[Pasted image 20231026091817.png]]
![[Pasted image 20231026091826.png]]
# 1.10.2 `自定义 Error，扩展 Error` (2023/10/19)[点击](https://zh.javascript.info/custom-errors)
## 自定义 Error，扩展 Error
* HttpError：网络操作中的 error
* DbError：数据库操作中的 error
* NotFoundError：搜索操作中的 error
* 自定义的 error 应该支持基本的 error 的属性
	*  `message`，`name`，并且最好还有 `stack`。但是它们也可能会有其他属于它们自己的属性，
	* 例如，`HttpError` 对象可能会有一个 `statusCode` 属性，属性值可能为 `404`、`403` 或 `500` 等。
	* 从技术上讲，我们自定义的 error 不需要从 `Error` 中继承。但是，如果我们继承，那么就可以使用 `obj instanceof Error` 来识别 error 对象。因此，最好继承它。
	* 随着开发的应用程序的增长，我们自己的 error 自然会形成形成一个层次结构（hierarchy）。例如，`HttpTimeoutError` 可能继承自 `HttpError`
## [扩展 Error](https://zh.javascript.info/custom-errors#kuo-zhan-error)

我们的函数 `readUser(json)` 不仅会读取 JSON，还会检查（“验证”）数据。如果没有所必须的字段，或者（字段的）格式错误，那么就会出现一个 error。并且这些并不是 `SyntaxError`，因为这些数据在语法上是正确的，这些是另一种错误。我们称之为 `ValidationError`，并为之创建一个类。这种类型的错误也应该包含有关违规字段的信息。

我们的 `ValidationError` 类应该继承自 `Error` 类。
`Error` 类是内建的，但这是其近似代码，所以我们可以了解我们要扩展的内容
![[Pasted image 20231026093525.png]]
现在让我们从其中继承 `ValidationError`
![[Pasted image 20231026093559.png]]
## [深入继承](https://zh.javascript.info/custom-errors#shen-ru-ji-cheng)
![[Pasted image 20231026101137.png]]
## [包装异常](https://zh.javascript.info/custom-errors#bao-zhuang-yi-chang)

```js[Plunker - Fork from https://zh.javascript.info/custom-errors (plnkr.co)](https://plnkr.co/edit/?p=preview&preview)
class ReadError extends Error {
  constructor(message, cause) {
    super(message);
    this.cause = cause;
    this.name = 'ReadError';
  }
}

class ValidationError extends Error { /*...*/ }
class PropertyRequiredError extends ValidationError { /* ... */ }

function validateUser(user) {
  if (!user.age) {
    throw new PropertyRequiredError("age");
  }

  if (!user.name) {
    throw new PropertyRequiredError("name");
  }
}

function readUser(json) {
  let user;

  try {
    user = JSON.parse(json);
  } catch (err) {
    if (err instanceof SyntaxError) {
      throw new ReadError("Syntax Error", err);
    } else {
      throw err;
    }
  }

  try {
    validateUser(user);
  } catch (err) {
    if (err instanceof ValidationError) {
      throw new ReadError("Validation Error", err);
    } else {
      throw err;
    }
  }

}

try {
  readUser('{bad json}');
} catch (e) {
  if (e instanceof ReadError) {
    alert(e);
    // Original error: SyntaxError: Unexpected token b in JSON at position 1
    alert("Original error: " + e.cause);
  } else {
    throw e;
  }
}

```
所以外部代码检查 `instanceof ReadError`，并且它的确是。不必列出所有可能的 error 类型。

这种方法被称为“包装异常（wrapping exceptions）”，因为我们将“低级别”的异常“包装”到了更抽象的 `ReadError` 中。它被广泛应用于面向对象的编程中。
## [总结](https://zh.javascript.info/custom-errors#zong-jie)

- 我们可以正常地从 `Error` 和其他内建的 error 类中进行继承。我们只需要注意 `name` 属性以及不要忘了调用 `super`。
- 我们可以使用 `instanceof` 来检查特定的 error。但有时我们有来自第三方库的 error 对象，并且在这儿没有简单的方法来获取它的类。那么可以将 `name` 属性用于这一类的检查。
- 包装异常是一项广泛应用的技术：用于处理低级别异常并创建高级别 error 而不是各种低级别 error 的函数。在上面的示例中，低级别异常有时会成为该对象的属性，例如 `err.cause`，但这不是严格要求的。