---
created: 2023-11-03T22:29
updated: 2023-11-06T12:24
---
# 使用 promise 进行错误处理
promise 链在错误（error）处理中十分强大。当一个 promise 被 reject 时，控制权将移交至最近的 rejection 处理程序。这在实际开发中非常方便。
正如你所看到的，`.catch` 不必是立即的。它可能在一个或多个 `.then` 之后出现。

或者，可能该网站一切正常，但响应不是有效的 JSON。捕获所有 error 的最简单的方法是，将 `.catch` 附加到链的末尾

通常情况下，这样的 `.catch` 根本不会被触发。但是如果上述任意一个 promise rejected（网络问题或者无效的 json 或其他），`.catch` 就会捕获它。
```html
<!DOCTYPE html>
<script>
"use strict";

fetch('/article/promise-chaining/user.json')
  .then(response => response.json())
  .then(user => fetch(`https://api.github.com/users/${user.name}`))
  .then(response => response.json())
  .then(githubUser => new Promise((resolve, reject) => {
    let img = document.createElement('img');
    img.src = githubUser.avatar_url;
    img.className = "promise-avatar-example";
    document.body.append(img);

    setTimeout(() => {
      img.remove();
      resolve(githubUser);
    }, 3000);
  }))
  .catch(error => alert(error.message));
</script>

```
## [隐式 try…catch](https://zh.javascript.info/promise-error-handling#yin-shi-trycatch)
promise 的执行者（executor）和 promise 的处理程序周围有一个“隐式的 `try..catch`”。如果发生异常，它就会被捕获，并被视为 rejection 进行处理。
![[Pasted image 20231026140701.png]]
在 executor 周围的“隐式 `try..catch`”自动捕获了 error，并将其变为 rejected promise。

这不仅仅发生在 executor 函数中，同样也发生在其处理程序中。如果我们在 `.then` 处理程序中 `throw`，这意味着 promise rejected，因此控制权移交至最近的 error 处理程序。
![[Pasted image 20231026140742.png]]
对于所有的 error 都会发生这种情况，而不仅仅是由 `throw` 语句导致的这些 error。例如，一个编程错误
![[Pasted image 20231026140757.png]]
最后的 `.catch` 不仅会捕获显式的 rejection，还会捕获它上面的处理程序中意外出现的 error。

## [再次抛出（Rethrowing）](https://zh.javascript.info/promise-error-handling#zai-ci-pao-chu-rethrowing)
正如我们已经注意到的，链尾端的 `.catch` 的表现有点像 `try..catch`。我们可能有许多个 `.then` 处理程序，然后在尾端使用一个 `.catch` 处理上面的所有 error。
在常规的 `try..catch` 中，我们可以分析 error，如果我们无法处理它，可以将其再次抛出。对于 promise 来说，这也是可以的。
如果我们在 `.catch` 中 `throw`，那么控制权就会被移交到下一个最近的 error 处理程序。如果我们处理该 error 并正常完成，那么它将继续到最近的成功的 `.then` 处理程序。
![[Pasted image 20231026140938.png]]
这里 `.catch` 块正常完成。所以下一个成功的 `.then` 处理程序就会被调用。

在下面的例子中，我们可以看到 `.catch` 的另一种情况。`(*)` 行的处理程序捕获了 error，但无法处理它（例如，它只知道如何处理 `URIError`），所以它将其再次抛出
![[Pasted image 20231026140956.png]]
执行从第一个 `.catch` `(*)` 沿着链跳转至下一个 `(**)`。
## [未处理的 rejection](https://zh.javascript.info/promise-error-handling#wei-chu-li-de-rejection)

如果出现 error，promise 的状态将变为 “rejected”，然后执行应该跳转至最近的 rejection 处理程序。但上面这个例子中并没有这样的处理程序。因此 error 会“卡住”。没有代码来处理它。
在实际开发中，就像代码中常规的未处理的 error 一样，这意味着某些东西出了问题。

当发生一个常规的 error 并且未被 `try..catch` 捕获时会发生什么？脚本死了，并在控制台中留下了一个信息。对于在 promise 中未被处理的 rejection，也会发生类似的事。

JavaScript 引擎会跟踪此类 rejection，在这种情况下会生成一个全局的 error。如果你运行上面这个代码，你可以在控制台中看到。
在浏览器中，我们可以使用 `unhandledrejection` 事件来捕获这类 error：
```html
<!DOCTYPE html>
<script>
"use strict";

window.addEventListener('unhandledrejection', function(event) {
  // 这个事件对象有两个特殊的属性：
  alert(event.promise); // [object Promise] —— 生成该全局 error 的 promise
  alert(event.reason); // Error: Whoops! —— 未处理的 error 对象
});

new Promise(function() {
  throw new Error("Whoops!");
}); // 没有用来处理 error 的 catch
</script>

```
这个事件是 [HTML 标准](https://html.spec.whatwg.org/multipage/webappapis.html#unhandled-promise-rejections) 的一部分。

如果出现了一个 error，并且在这没有 `.catch`，那么 `unhandledrejection` 处理程序就会被触发，并获取具有 error 相关信息的 `event` 对象，所以我们就能做一些后续处理了。

通常此类 error 是无法恢复的，所以我们最好的解决方案是将问题告知用户，并且可以将事件报告给服务器。

在 Node.js 等非浏览器环境中，有其他用于跟踪未处理的 error 的方法。

## [总结](https://zh.javascript.info/promise-error-handling#zong-jie)

- `.catch` 处理 promise 中的各种 error：在 `reject()` 调用中的，或者在处理程序中抛出的 error。
- 如果给定 `.then` 的第二个参数（即 error 处理程序），那么 `.then` 也会以相同的方式捕获 error。
- 我们应该将 `.catch` 准确地放到我们想要处理 error，并知道如何处理这些 error 的地方。处理程序应该分析 error（可以自定义 error 类来帮助分析）并再次抛出未知的 error（它们可能是编程错误）。
- 如果没有办法从 error 中恢复，不使用 `.catch` 也可以。
- 在任何情况下我们都应该有 `unhandledrejection` 事件处理程序（用于浏览器，以及其他环境的模拟），以跟踪未处理的 error 并告知用户（可能还有我们的服务器）有关信息，以使我们的应用程序永远不会“死掉”。